Workbook

Sheet ấp Trường Bình
A1: STT | B1: Họ và tên | C1: Số Mã Bảo Hiểm | D1: Tra bên BHXH | E1: Ngày tháng năm sinh | F1: Số Định danh | G1: Ngày cấp | H1: Mối quan hệ | I1: Tuổi | J1: Điện thoại | K1: Đi nước ngoài | O1: Nghề nghiệp | P1: Lúa/diện tích | Q1: Vườn | T1: Rau màu | V1: Ao | X1: Chăn nuôi | Z1: Ghi chú
K2: Du học | L2: Lấy chồng | M2: XKLD | N2: Định cư | Q2: Cây | R2: số lượng | S2: diện tích | T2: Tên Rau | U2: Diện tích | V2: Tên vật nuôi | W2: số lượng/m2 | X2: Gia xúc | Y2: gia cầm
B3: Lê Thị Yến Ngọc | C3: không có | D3: =IFERROR(INDEX(BHXH!B:B,MATCH($F3,BHXH!D:D,0)),"không có") -> không có | E3: 25/01/2011 | F3: 093311001451 | G3: 45700 | H3: thành viên | I3: =DATEDIF($E3, TODAY(), "Y") -> #VALUE!
B4: Nguyễn Ngô Yến Nhi | C4: 9321653748 | D4: =IFERROR(INDEX(BHXH!B:B,MATCH($F4,BHXH!D:D,0)),"không có") -> 9321653748 | E4: 16/06/2011 | F4: 093311008474 | G4: 45918 | H4: thành viên | I4: =DATEDIF($E4, TODAY(), "Y") -> #VALUE!
B5: Nguyễn Lâm Chấn Khang | C5: 9320952733 | D5: =IFERROR(INDEX(BHXH!B:B,MATCH($F5,BHXH!D:D,0)),"không có") -> 9320952733 | E5: 02/09/2011 | F5: 093211008469 | G5: 45957 | H5: thành viên | I5: =DATEDIF($E5, TODAY(), "Y") -> 15
B6: Nguyễn Gia Kỳ | C6: 9321049671 | D6: =IFERROR(INDEX(BHXH!B:B,MATCH($F6,BHXH!D:D,0)),"không có") -> 9321049671 | E6: 29/01/2011 | F6: 093211001413 | G6: 46051 | H6: thành viên | I6: =DATEDIF($E6, TODAY(), "Y") -> #VALUE!
B7: Võ Lê Thanh Khánh | C7: 9123367865 | D7: =IFERROR(INDEX(BHXH!B:B,MATCH($F7,BHXH!D:D,0)),"không có") -> 9123367865 | E7: 02/01/2011 | F7: 093211001330 | G7: 45993 | H7: thành viên | I7: =DATEDIF($E7, TODAY(), "Y") -> 15
B8: Hồ Thị Diễm Khanh | C8: 9321019922 | D8: =IFERROR(INDEX(BHXH!B:B,MATCH($F8,BHXH!D:D,0)),"không có") -> 9321019922 | E8: 03/07/2011 | F8: 093311004383 | G8: 46013 | H8: thành viên | I8: =DATEDIF($E8, TODAY(), "Y") -> 15
B9: Lê Quốc Huy | C9: 9320996221 | D9: =IFERROR(INDEX(BHXH!B:B,MATCH($F9,BHXH!D:D,0)),"không có") -> 9320996221 | E9: 09/11/2010 | F9: 093210001408 | G9: 45769 | H9: thành viên | I9: =DATEDIF($E9, TODAY(), "Y") -> 16
B10: Lê Hoàng Huỳnh Giao | C10: 9321010773 | D10: =IFERROR(INDEX(BHXH!B:B,MATCH($F10,BHXH!D:D,0)),"không có") -> 9321010773 | E10: 02/08/2011 | F10: 093311001891 | G10: 45874 | H10: thành viên | I10: =DATEDIF($E10, TODAY(), "Y") -> 15
B11: Trần Huỳnh Phát | C11: 9321715285 | D11: =IFERROR(INDEX(BHXH!B:B,MATCH($F11,BHXH!D:D,0)),"không có") -> 9321715285 | E11: 17/01/2010 | F11: 093210007382 | G11: 45693 | H11: thành viên | I11: =DATEDIF($E11, TODAY(), "Y") -> #VALUE!
B12: Đặng Quốc Khánh | C12: 9320955503 | D12: =IFERROR(INDEX(BHXH!B:B,MATCH($F12,BHXH!D:D,0)),"không có") -> không có | E12: 20/08/2010 | F12: 093210000616 | G12: 45958 | H12: thành viên | I12: =DATEDIF($E12, TODAY(), "Y") -> #VALUE!
B13: Nguyễn Huỳnh Thiên Phú | C13: 9320987367 | E13: 12/08/2012 | F13: 093212008118 | G13: 46164 | H13: thành viên | I13: =DATEDIF($E13, TODAY(), "Y") -> 13
B14: Đặng Quốc Khánh | C14: 9320955503 | D14: =IFERROR(INDEX(BHXH!B:B,MATCH($F14,BHXH!D:D,0)),"không có") -> không có | E14: 20/08/2010 | F14: 093210000616 | G14: 45958 | H14: thành viên | I14: =DATEDIF($E14, TODAY(), "Y") -> #VALUE!
B15: Nguyễn Huỳnh Bảo Châu | C15: 9321985782 | E15: 12/03/2019 | F15: 093319002591 | G15: 46164 | H15: thành viên | I15: =DATEDIF($E15, TODAY(), "Y") -> 6
B16: Võ Thị Mỹ Trân | C16: 9320954915 | D16: =IFERROR(INDEX(BHXH!B:B,MATCH($F16,BHXH!D:D,0)),"không có") -> 9320954915 | E16: 28/10/2009 | F16: 093309003365 | G16: 45282 | H16: thành viên | I16: =DATEDIF($E16, TODAY(), "Y") -> #VALUE!
B17: Lê Văn Thái | C17: 9321715188 | D17: =IFERROR(INDEX(BHXH!B:B,MATCH($F17,BHXH!D:D,0)),"không có") -> 9321715188 | E17: 25/04/2010 | F17: 091210015219 | G17: 45623 | H17: thành viên | I17: =DATEDIF($E17, TODAY(), "Y") -> #VALUE!
B18: Huỳnh Gia Tuệ | C18: 9321985801 | E18: 29/04/2019 | F18: 093319003274 | G18: 46230 | H18: thành viên | I18: =DATEDIF($E18, TODAY(), "Y") -> #VALUE!
B19: Trần Văn Được | C19: 9321674476 | D19: =IFERROR(INDEX(BHXH!B:B,MATCH($F19,BHXH!D:D,0)),"không có") -> không có | E19: 06/05/2010 | F19: 093210000034 | H19: thành viên | I19: =DATEDIF($E19, TODAY(), "Y") -> 16
B20: Lê Thị Kim Thoa | C20: 9222512532 | D20: =IFERROR(INDEX(BHXH!B:B,MATCH($F20,BHXH!D:D,0)),"không có") -> 9222512532 | E20: 40384 | F20: 092310001935 | G20: 45790 | H20: thành viên | I20: =DATEDIF($E20, TODAY(), "Y") -> 16
B21: Trần Đăng Khoa | C21: không có | D21: =IFERROR(INDEX(BHXH!B:B,MATCH($F21,BHXH!D:D,0)),"không có") -> không có | E21: 27/10/2009 | F21: 093209001302 | H21: thành viên | I21: =DATEDIF($E21, TODAY(), "Y") -> #VALUE!
B22: Nguyễn Ngọc Như Ý | C22: 9222869197 | E22: 22/03/2014 | F22: 093314003626 | G22: 46248 | H22: thành viên | I22: =DATEDIF($E22, TODAY(), "Y") -> #VALUE!
B23: Đỗ Thị Âm | C23: 9320998871 | D23: =IFERROR(INDEX(BHXH!B:B,MATCH($F23,BHXH!D:D,0)),"không có") -> không có | E23: 15/06/2010 | F23: 093310006717 | H23: thành viên | I23: =DATEDIF($E23, TODAY(), "Y") -> #VALUE! | Z23: Bị Câm
B24: Nguyễn Minh Khôi | E24: 44789 | F24: 091222009232 | H24: thành viên | I24: =DATEDIF($E24, TODAY(), "Y") -> 4
B25: Phạm Đức Duy | C25: 9321003834 | D25: =IFERROR(INDEX(BHXH!B:B,MATCH($F25,BHXH!D:D,0)),"không có") -> 9321003834 | E25: 29/10/2009 | F25: 093209006941 | G25: 45924 | H25: thành viên | I25: =DATEDIF($E25, TODAY(), "Y") -> #VALUE!
B26: Huỳnh Thị Ngọc Lan | C26: 9320993170 | D26: =IFERROR(INDEX(BHXH!B:B,MATCH($F26,BHXH!D:D,0)),"không có") -> 9320993170 | E26: 13/05/2010 | F26: 093310004570 | G26: 46036 | H26: thành viên | I26: =DATEDIF($E26, TODAY(), "Y") -> #VALUE!
B27: Trương Thị Bảo Yến | C27: 9321665316 | D27: =IFERROR(INDEX(BHXH!B:B,MATCH($F27,BHXH!D:D,0)),"không có") -> 9321665316 | E27: 04/09/2010 | F27: 093310002215 | G27: 45585 | H27: thành viên | I27: =DATEDIF($E27, TODAY(), "Y") -> 16
B28: Nguyễn Văn Nhiều | C28: 9321715239 | D28: =IFERROR(INDEX(BHXH!B:B,MATCH($F28,BHXH!D:D,0)),"không có") -> 9321715239 | E28: 04/10/2009 | F28: 093209004654 | G28: 45050 | H28: thành viên | I28: =DATEDIF($E28, TODAY(), "Y") -> 17
B29: Huỳnh Ngọc Trân | C29: 9320979076 | D29: =IFERROR(INDEX(BHXH!B:B,MATCH($F29,BHXH!D:D,0)),"không có") -> 9320979076 | E29: 11/12/2008 | F29: 093308007358 | G29: 45012 | H29: thành viên | I29: =DATEDIF($E29, TODAY(), "Y") -> 17
B30: Lê Thị Yến Như | C30: không có | D30: =IFERROR(INDEX(BHXH!B:B,MATCH($F30,BHXH!D:D,0)),"không có") -> không có | E30: 04/03/2009 | F30: 093309003153 | G30: 45208 | H30: thành viên | I30: =DATEDIF($E30, TODAY(), "Y") -> 17
B31: Phạm Hồng Nghĩa | C31: 9321711955 | D31: =IFERROR(INDEX(BHXH!B:B,MATCH($F31,BHXH!D:D,0)),"không có") -> 9321711955 | E31: 22/11/2008 | F31: 093208003795 | G31: 45012 | H31: thành viên | I31: =DATEDIF($E31, TODAY(), "Y") -> #VALUE!
B32: Phạm Thị Bé Ngọc | C32: 9320979078 | D32: =IFERROR(INDEX(BHXH!B:B,MATCH($F32,BHXH!D:D,0)),"không có") -> 9320979078 | E32: 14/07/2009 | F32: 093309006664 | G32: 46084 | H32: thành viên | I32: =DATEDIF($E32, TODAY(), "Y") -> #VALUE!
B33: Loh Thiên Phúc | C33: 9321942060 | E33: 14/02/2018 | F33: 093218002691 | H33: thành viên | I33: =DATEDIF($E33, TODAY(), "Y") -> #VALUE! | L33: x
B34: Nguyễn Hoàng Kha | C34: 9321024668 | D34: =IFERROR(INDEX(BHXH!B:B,MATCH($F34,BHXH!D:D,0)),"không có") -> không có | E34: 02/05/2009 | F34: 093209002948 | G34: 45012 | H34: thành viên | I34: =DATEDIF($E34, TODAY(), "Y") -> 17
B35: Nguyễn Định Quốc | C35: 9320992022 | D35: =IFERROR(INDEX(BHXH!B:B,MATCH($F35,BHXH!D:D,0)),"không có") -> 9320992022 | E35: 15/10/2008 | F35: 093208002380 | G35: 44915 | H35: thành viên | I35: =DATEDIF($E35, TODAY(), "Y") -> #VALUE!
B36: Huỳnh Nhã Nghi Đình | C36: 9321950966 | E36: 15/05/2019 | F36: 093319006365 | G36: 46198 | H36: thành viên | I36: =DATEDIF($E36, TODAY(), "Y") -> #VALUE!
B37: Huỳnh Khôi Nguyên | C37: 9322028961 | E37: 07/06/2023 | F37: 093223002298 | H37: thành viên | I37: =DATEDIF($E37, TODAY(), "Y") -> 3
B38: Trương Tâm Nghi | C38: 9320994931 | D38: =IFERROR(INDEX(BHXH!B:B,MATCH($F38,BHXH!D:D,0)),"không có") -> 9320994931 | E38: 24/05/2009 | F38: 093309004934 | G38: 45107 | H38: thành viên | I38: =DATEDIF($E38, TODAY(), "Y") -> #VALUE!
B39: Huỳnh Tống Gia Vỹ | C39: 9223329147 | E39: 18/07/2025 | F39: 092225003500 | H39: thành viên | I39: =DATEDIF($E39, TODAY(), "Y") -> #VALUE!
B40: Bùi Thị Ngà | C40: 7423151020 | D40: =IFERROR(INDEX(BHXH!B:B,MATCH($F40,BHXH!D:D,0)),"không có") -> 7423151020 | E40: 21/05/2009 | F40: 093309001079 | G40: 45456 | H40: thành viên | I40: =DATEDIF($E40, TODAY(), "Y") -> #VALUE!
...

Sheet BHXH
A1: Họ và tên | B1: Mã số bảo hiểm y tế | C1: Ngày sinh | D1: Số căn cước công dân/Định danh cá nhân | G1: =IFERROR(INDEX(BHXH!B:B,MATCH($F3,BHXH!D:D,0)),"không có")
A2: B | B2: 1 | D2: 2
A3: Trương Thị Lụa | B3: 0204015408 | C3: 01/01/1976 | D3: 093176004419
A4: Lê Thị Kim Tám | B4: 7410191368 | C4: 01/01/1990 | D4: 093190004973
A5: Nguyễn Thị Nhường | B5: 7410212696 | C5: 01/01/1971 | D5: 093171002445
A6: Bùi Quốc Phong | B6: 7414136077 | C6: 01/01/1991 | D6: 093091005744
A7: Lê Thị Diễm Thúy | B7: 7415024225 | C7: 30/06/1996 | D7: 093196003758
A8: Huỳnh Thị Kim Thoa | B8: 7415143880 | C8: 16/06/1994 | D8: 093194007115
A9: Đặng Chí Thanh | B9: 7416189336 | C9: 20/10/1988 | D9: 093088010187
A10: Dương Hồng Diễm | B10: 7416332232 | C10: 29/05/1999 | D10: 093199004042
A11: Lương Thị Thanh Ngân | B11: 7422362727 | C11: 11/11/2004 | D11: 074304003977
A12: Nguyễn Kiên Giang | B12: 7422405676 | C12: 01/01/1985 | D12: 093085013570
A13: Bùi Thị Cẩm Giang | B13: 7423122208 | C13: 16/01/2008 | D13: 093308006288
A14: Trang Ngọc Vân | B14: 7423241809 | C14: 31/12/1989 | D14: 093089010272 | H14: 47
A15: Phạm Hồng Tuấn | B15: 7423500209 | C15: 01/01/1977 | D15: 093077000732
A16: Phạm Văn Lấn | B16: 7423969585 | C16: 06/08/1982 | D16: 092082006980
A17: Lê Thanh Bình | B17: 7511034816 | C17: 01/01/1988 | D17: 093088001219
A18: Lê Thanh Tùng | B18: 7514030054 | C18: 01/01/1983 | D18: 093083001223
A19: Nguyễn Thị Mỹ Ly | B19: 7516122593 | C19: 01/01/1981 | D19: 092181015539
A20: Võ Tấn Hải | B20: 7516200336 | C20: 01/12/1989 | D20: 093089001051
A21: Hà Hải Nam | B21: 7910497964 | C21: 15/10/1992 | D21: 093092000655
A22: Nguyễn Văn Hiện | B22: 7911344179 | C22: 09/12/1993 | D22: 093093000241
A23: Trần Thị Rồi | B23: 7913198323 | C23: 01/01/1971 | D23: 093171007455
A24: Huỳnh Thị Hồng Lan | B24: 7914240007 | C24: 01/01/1981 | D24: 093181002186
A25: Nguyễn Văn Duẩn | B25: 7915132891 | C25: 09/10/1988 | D25: 093088005946
A26: Nguyễn Văn Thanh | B26: 7915226558 | C26: 07/04/1990 | D26: 093090001189
... A2205: Nguyễn Đình Phi | B2205: 9321023905 | C2205: 13/08/2005 | D2205: 093205009054
